<?xml version="1.0" encoding="utf-8" ?>
<!-- This URDF was automatically created by SolidWorks to URDF Exporter! Originally created by Stephen Brawner (brawner@gmail.com) 
     Commit Version: 1.6.0-4-g7f85cfe  Build Version: 1.6.7995.38578
     For more information, please see http://wiki.ros.org/sw_urdf_exporter -->
<robot name="arx5_description" xmlns:xacro="http://www.ros.org/wiki/xacro">
    <!-- <link name="footprint"/> -->

    <xacro:include filename="$(find tracer_description)/urdf/tracer_v1.xacro"/>
    <xacro:include filename="$(find livox_laser_simulation)/urdf/livox_mid360.xacro"/>
    <xacro:include filename="$(find realsense_ros_gazebo)/xacro/depthcam.xacro"/>

    <link name="footprint">
    </link>
    <link name="robot::footprint">
    </link>
    <xacro:realsense_d435 sensor_name="camera_l" parent_link="fl_link6" rate="10">
        <origin rpy="0 0 0 " xyz="0.06 0 0.06"/>
    </xacro:realsense_d435>
    <xacro:realsense_d435 sensor_name="camera_r" parent_link="fr_link6" rate="10">
        <origin rpy="0 0 0 " xyz="0.06 0 0.06"/>
    </xacro:realsense_d435>
    <xacro:realsense_d435 sensor_name="camera_f" parent_link="footprint" rate="10">
        <origin rpy="0 0 0 " xyz="0.17 -0.01 0.84"/>
    </xacro:realsense_d435>

    <joint name="box_joint" type="fixed">
        <origin xyz="0 0 0.15" rpy="0 0 0" />
        <parent link="footprint" />
        <child link="base_link" />
        <axis xyz="0 0 0" />
    </joint>
    <joint name="livox_joint" type="fixed">
        <origin xyz="0.23 0 0.19" rpy="0 0 0" />
        <parent link="footprint" />
        <child link="livox_base" />
        <axis xyz="0 0 0" />
    </joint>
    <joint name="robot_footprint_joint" type="fixed">
        <origin xyz="0.18 0 0.29" rpy="0 0 0" />
        <parent link="footprint" />
        <child link="robot::footprint" />
        <axis xyz="0 0 0" />
    </joint>
    <link name="box1_Link">
        <inertial>
            <origin xyz="-0.17227 -0.0012276 0.023432" rpy="0 0 0" />
            <mass value="0.00014994" />
            <inertia ixx="0.012264" ixy="-9.2432E-06" ixz="0.0001761" iyy="0.0045226" iyz="-0.00063248" izz="0.016558" />
        </inertial>
        <visual>
            <origin xyz="0 0 0" rpy="-0.05 0 0" />
            <geometry>
                <mesh filename="package://aloha/meshes/box1_Link.STL" />
            </geometry>
            <material name="">
                <color rgba="0.79216 0.81961 0.93333 1" />
            </material>
        </visual>
        <collision>
            <origin xyz="0 0 0" rpy="-0.05 0 0" />
            <geometry>
                <mesh filename="package://aloha/meshes/box1_Link.STL" />
            </geometry>
        </collision>
    </link>
    <joint name="box1" type="fixed">
        <origin xyz="0 0 0.15" rpy="0 0 0" />
        <parent link="footprint" />
        <child link="box1_Link" />
        <axis xyz="0 0 0" />
    </joint>
    <link name="box2_Link">
        <inertial>
            <origin xyz="0.015107 -0.027922 0.00013672" rpy="0 0 0" />
            <mass value="3.736" />
            <inertia ixx="0.097545" ixy="-9.2609E-06" ixz="0.00015366" iyy="0.045841" iyz="-0.0020459" izz="0.084773" />
        </inertial>
        <visual>
            <origin xyz="0 0 0" rpy="-0.05 0 0" />
            <geometry>
                <mesh filename="package://aloha/meshes/box2_Link.STL" />
            </geometry>
            <material name="">
                <color rgba="0.79216 0.81961 0.93333 1" />
            </material>
        </visual>
        <collision>
            <origin xyz="0 0 0" rpy="-0.05 0 0" />
            <geometry>
                <mesh filename="package://aloha/meshes/box2_Link.STL" />
            </geometry>
        </collision>
    </link>
    <joint name="box2" type="fixed">
        <origin xyz="0 0 0" rpy="0 0 0" />
        <parent link="box1_Link" />
        <child link="box2_Link" />
        <axis xyz="0 0 0" />
    </joint>
    <!--***************************** front-left ****************************** -->
    <link name="fl_base_link">
        <inertial>
            <origin xyz="-2.9972E-05 3.056E-05 0.027301" rpy="0 0 0" />
            <mass value="0.44038" />
            <inertia ixx="0.00017" ixy="0.00000" ixz="0.00000" iyy="0.00018" iyz="0.00000" izz="0.00016" />
        </inertial>
        <visual>
            <origin xyz="0 0 0" rpy="0 0 0" />
            <geometry>
                <mesh filename="package://arx5_description/meshes/base_link.STL" />
            </geometry>
            <material name="">
                <color rgba="0.75294 0.75294 0.75294 1" />
            </material>
        </visual>
        <collision>
            <origin xyz="0 0 0" rpy="0 0 0" />
            <geometry>
                <mesh filename="package://arx5_description/meshes/base_link.STL" />
            </geometry>
        </collision>
    </link>
    <joint name="fl_base_joint" type="fixed">
        <origin xyz="0.233 0.3 0.7775" rpy="0.0 0.0 0.0" />
        <parent link="footprint" />
        <child link="fl_base_link" />
        <axis xyz="0.0 0.0 1.0" />
    </joint>
    <link name="fl_link1">
        <inertial>
            <origin xyz="0.00609525411893452 -0.00429681977500749 0.0179590247477389" rpy="0 0 0" />
            <mass value="0.0608351104988555" />
            <inertia ixx="0.00008" ixy="0.00000" ixz="0.00001" iyy="0.00003" iyz="0.00000" izz="0.00007" />
        </inertial>
        <visual>
            <origin xyz="0 0 0" rpy="0 0 0" />
            <geometry>
                <mesh filename="package://arx5_description/meshes/link1.STL" />
            </geometry>
            <material name="">
                <color rgba="0.752941176470588 0.752941176470588 0.752941176470588 1" />
            </material>
        </visual>
        <collision>
            <origin xyz="0 0 0" rpy="0 0 0" />
            <geometry>
                <mesh filename="package://arx5_description/meshes/link1.STL" />
            </geometry>
        </collision>
    </link>
    <joint name="fl_joint1" type="revolute">
        <origin xyz="0 0 0.0603" rpy="0 0 0" />
        <parent link="fl_base_link" />
        <child link="fl_link1" />
        <axis xyz="0 0 1" />
        <limit lower="-10" upper="10" effort="100" velocity="1000" />
    </joint>
    <link name="fl_link2">
        <inertial>
            <origin xyz="-0.132382037190567 0.00220380675553821 0.000111790164679923" rpy="0 0 0" />
            <mass value="1.0733279014126" />
            <inertia ixx="0.00050" ixy="0.00000" ixz="-0.00004" iyy="0.01596" iyz="0.00000" izz="0.01602" />
        </inertial>
        <visual>
            <origin xyz="0 0 0" rpy="0 0 0" />
            <geometry>
                <mesh filename="package://arx5_description/meshes/link2.STL" />
            </geometry>
            <material name="">
                <color rgba="0.752941176470588 0.752941176470588 0.752941176470588 1" />
            </material>
        </visual>
        <collision>
            <origin xyz="0 0 0" rpy="0 0 0" />
            <geometry>
                <mesh filename="package://arx5_description/meshes/link2.STL" />
            </geometry>
        </collision>
    </link>
    <joint name="fl_joint2" type="revolute">
        <origin xyz="0.02 0 0.0402" rpy="0 0 0" />
        <parent link="fl_link1" />
        <child link="fl_link2" />
        <axis xyz="0 1 0" />
        <limit lower="-10" upper="10" effort="100" velocity="1000" />
    </joint>
    <link name="fl_link3">
        <inertial>
            <origin xyz="0.187203287369961 -0.000305676361444925 -0.0514832866415513" rpy="0 0 0" />
            <mass value="0.499404738025019" />
            <inertia ixx="0.00033" ixy="-0.00006" ixz="-0.00039" iyy="0.00387" iyz="0.00001" izz="0.00383" />
        </inertial>
        <visual>
            <origin xyz="0 0 0" rpy="0 0 0" />
            <geometry>
                <mesh filename="package://arx5_description/meshes/link3.STL" />
            </geometry>
            <material name="">
                <color rgba="0.752941176470588 0.752941176470588 0.752941176470588 1" />
            </material>
        </visual>
        <collision>
            <origin xyz="0 0 0" rpy="0 0 0" />
            <geometry>
                <mesh filename="package://arx5_description/meshes/link3.STL" />
            </geometry>
        </collision>
    </link>
    <joint name="fl_joint3" type="revolute">
        <origin xyz="-0.264 0 0" rpy="-3.1416 0 0" />
        <parent link="fl_link2" />
        <child link="fl_link3" />
        <axis xyz="0 1 0" />
        <limit lower="-10" upper="10" effort="100" velocity="1000" />
    </joint>
    <link name="fl_link4">
        <inertial>
            <origin xyz="0.0388884702662706 0.00295168681334743 -0.0353282735009622" rpy="0 0 0" />
            <mass value="0.0809712553169999" />
            <inertia ixx="0.00013" ixy="-0.00001" ixz="-0.00006" iyy="0.00016" iyz="0.00001" izz="0.00010" />
        </inertial>
        <visual>
            <origin xyz="0 0 0" rpy="0 0 0" />
            <geometry>
                <mesh filename="package://arx5_description/meshes/link4.STL" />
            </geometry>
            <material name="">
                <color rgba="0.898039215686275 0.917647058823529 0.929411764705882 1" />
            </material>
        </visual>
        <collision>
            <origin xyz="0 0 0" rpy="0 0 0" />
            <geometry>
                <mesh filename="package://arx5_description/meshes/link4.STL" />
            </geometry>
        </collision>
    </link>
    <joint name="fl_joint4" type="revolute">
        <origin xyz="0.245 0 -0.056" rpy="0 0 0" />
        <parent link="fl_link3" />
        <child link="fl_link4" />
        <axis xyz="0 1 0" />
        <limit lower="-10" upper="10" effort="100" velocity="1000" />
    </joint>
    <link name="fl_link5">
        <inertial>
            <origin xyz="0.00289956909960302 3.15826689885766E-05 0.0526188859211408" rpy="0 0 0" />
            <mass value="0.602357399313257" />
            <inertia ixx="0.00072" ixy="0.00000" ixz="0.00005" iyy="0.00069" iyz="0.00000" izz="0.00021" />
        </inertial>
        <visual>
            <origin xyz="0 0 0" rpy="0 0 0" />
            <geometry>
                <mesh filename="package://arx5_description/meshes/link5.STL" />
            </geometry>
            <material name="">
                <color rgba="0.752941176470588 0.752941176470588 0.752941176470588 1" />
            </material>
        </visual>
        <collision>
            <origin xyz="0 0 0" rpy="0 0 0" />
            <geometry>
                <mesh filename="package://arx5_description/meshes/link5.STL" />
            </geometry>
        </collision>
    </link>
    <joint name="fl_joint5" type="revolute">
        <origin xyz="0.06575 -0.001 -0.0825" rpy="0 0 0" />
        <parent link="fl_link4" />
        <child link="fl_link5" />
        <axis xyz="0 0 1" />
        <limit lower="-10" upper="10" effort="100" velocity="1000" />
    </joint>
    <link name="fl_link6">
        <inertial>
            <origin xyz="0.0471798400661976 0.000102970421835668 -0.000138510949393961" rpy="0 0 0" />
            <mass value="0.462244960775882" />
            <inertia ixx="0.00068" ixy="0.00000" ixz="0.00000" iyy="0.00036" iyz="-0.00001" izz="0.00091" />
        </inertial>
        <visual>
            <origin xyz="0 0 0" rpy="0 0 0" />
            <geometry>
                <mesh filename="package://arx5p2/meshes/link6.STL" />
            </geometry>
            <material name="">
                <color rgba="0.898039215686275 0.917647058823529 0.929411764705882 1" />
            </material>
        </visual>
        <collision>
            <origin xyz="0 0 0" rpy="0 0 0" />
            <geometry>
                <mesh filename="package://arx5p2/meshes/link6.STL" />
            </geometry>
        </collision>
    </link>
    <joint name="fl_joint6" type="revolute">
        <origin xyz="0.02845 0 0.0825" rpy="-3.1416 0 0" />
        <parent link="fl_link5" />
        <child link="fl_link6" />
        <axis xyz="1 0 0" />
        <limit lower="-10" upper="10" effort="100" velocity="1000" />
    </joint>
    <link name="fl_link7">
        <inertial>
            <origin xyz="-0.000327642774520215 -0.00482005374028087 -0.00167540868720402" rpy="0 0 0" />
            <mass value="0.0484016660227936" />
            <inertia ixx="0.00001" ixy="0.00000" ixz="0.00000" iyy="0.00002" iyz="0.00000" izz="0.00002" />
        </inertial>
        <visual>
            <origin xyz="0 0 0" rpy="0 0 0" />
            <geometry>
                <mesh filename="package://arx5p2/meshes/link7.STL" />
            </geometry>
            <material name="">
                <color rgba="0.898039215686275 0.917647058823529 0.929411764705882 1" />
            </material>
        </visual>
        <collision>
            <origin xyz="0 0 0" rpy="0 0 0" />
            <geometry>
                <mesh filename="package://arx5p2/meshes/link7.STL" />
            </geometry>
        </collision>
    </link>
    <joint name="fl_joint7" type="prismatic">
        <origin xyz="0.073574 0.024629 0" rpy="0 0 0" />
        <parent link="fl_link6" />
        <child link="fl_link7" />
        <axis xyz="0 1 0" />
        <limit lower="0" upper="0.04765" effort="100" velocity="100" />
    </joint>
    <link name="fl_link8">
        <inertial>
            <origin xyz="-0.000327643744208572 0.00482005363510456 0.000752972893839382" rpy="0 0 0" />
            <mass value="0.0484016646136083" />
            <inertia ixx="0.00001" ixy="0.00000" ixz="0.00000" iyy="0.00002" iyz="0.00000" izz="0.00002" />
        </inertial>
        <visual>
            <origin xyz="0 0 0" rpy="0 0 0" />
            <geometry>
                <mesh filename="package://arx5p2/meshes/link8.STL" />
            </geometry>
            <material name="">
                <color rgba="0.898039215686275 0.917647058823529 0.929411764705882 1" />
            </material>
        </visual>
        <collision>
            <origin xyz="0 0 0" rpy="0 0 0" />
            <geometry>
                <mesh filename="package://arx5p2/meshes/link8.STL" />
            </geometry>
        </collision>
    </link>
    <joint name="fl_joint8" type="prismatic">
        <origin xyz="0.073574 -0.024629 0" rpy="0 0 0" />
        <parent link="fl_link6" />
        <child link="fl_link8" />
        <axis xyz="0 -1 0" />
        <limit lower="0" upper="0.04765" effort="100" velocity="100" />
    </joint>
    <!--***************************** front-right ****************************** -->
    <link name="fr_base_link">
        <inertial>
            <origin xyz="-2.9972E-05 3.056E-05 0.027301" rpy="0 0 0" />
            <mass value="0.44038" />
            <inertia ixx="0.00017" ixy="0.00000" ixz="0.00000" iyy="0.00018" iyz="0.00000" izz="0.00016" />
        </inertial>
        <visual>
            <origin xyz="0 0 0" rpy="0 0 0" />
            <geometry>
                <mesh filename="package://arx5_description/meshes/base_link.STL" />
            </geometry>
            <material name="">
                <color rgba="0.75294 0.75294 0.75294 1" />
            </material>
        </visual>
        <collision>
            <origin xyz="0 0 0" rpy="0 0 0" />
            <geometry>
                <mesh filename="package://arx5_description/meshes/base_link.STL" />
            </geometry>
        </collision>
    </link>
    <joint name="fr_base_joint" type="fixed">
        <origin xyz="0.233 -0.307 0.7775" rpy="0.0 0.0 0.0" />
        <parent link="footprint" />
        <child link="fr_base_link" />
        <axis xyz="0.0 0.0 1.0" />
    </joint>
    <link name="fr_link1">
        <inertial>
            <origin xyz="0.00609525411893452 -0.00429681977500749 0.0179590247477389" rpy="0 0 0" />
            <mass value="0.0608351104988555" />
            <inertia ixx="0.00008" ixy="0.00000" ixz="0.00001" iyy="0.00003" iyz="0.00000" izz="0.00007" />
        </inertial>
        <visual>
            <origin xyz="0 0 0" rpy="0 0 0" />
            <geometry>
                <mesh filename="package://arx5_description/meshes/link1.STL" />
            </geometry>
            <material name="">
                <color rgba="0.752941176470588 0.752941176470588 0.752941176470588 1" />
            </material>
        </visual>
        <collision>
            <origin xyz="0 0 0" rpy="0 0 0" />
            <geometry>
                <mesh filename="package://arx5_description/meshes/link1.STL" />
            </geometry>
        </collision>
    </link>
    <joint name="fr_joint1" type="revolute">
        <origin xyz="0 0 0.0603" rpy="0 0 0" />
        <parent link="fr_base_link" />
        <child link="fr_link1" />
        <axis xyz="0 0 1" />
        <limit lower="-10" upper="10" effort="100" velocity="1000" />
    </joint>
    <link name="fr_link2">
        <inertial>
            <origin xyz="-0.132382037190567 0.00220380675553821 0.000111790164679923" rpy="0 0 0" />
            <mass value="1.0733279014126" />
            <inertia ixx="0.00050" ixy="0.00000" ixz="-0.00004" iyy="0.01596" iyz="0.00000" izz="0.01602" />
        </inertial>
        <visual>
            <origin xyz="0 0 0" rpy="0 0 0" />
            <geometry>
                <mesh filename="package://arx5_description/meshes/link2.STL" />
            </geometry>
            <material name="">
                <color rgba="0.752941176470588 0.752941176470588 0.752941176470588 1" />
            </material>
        </visual>
        <collision>
            <origin xyz="0 0 0" rpy="0 0 0" />
            <geometry>
                <mesh filename="package://arx5_description/meshes/link2.STL" />
            </geometry>
        </collision>
    </link>
    <joint name="fr_joint2" type="revolute">
        <origin xyz="0.02 0 0.0402" rpy="0 0 0" />
        <parent link="fr_link1" />
        <child link="fr_link2" />
        <axis xyz="0 1 0" />
        <limit lower="-10" upper="10" effort="100" velocity="1000" />
    </joint>
    <link name="fr_link3">
        <inertial>
            <origin xyz="0.187203287369961 -0.000305676361444925 -0.0514832866415513" rpy="0 0 0" />
            <mass value="0.499404738025019" />
            <inertia ixx="0.00033" ixy="-0.00006" ixz="-0.00039" iyy="0.00387" iyz="0.00001" izz="0.00383" />
        </inertial>
        <visual>
            <origin xyz="0 0 0" rpy="0 0 0" />
            <geometry>
                <mesh filename="package://arx5_description/meshes/link3.STL" />
            </geometry>
            <material name="">
                <color rgba="0.752941176470588 0.752941176470588 0.752941176470588 1" />
            </material>
        </visual>
        <collision>
            <origin xyz="0 0 0" rpy="0 0 0" />
            <geometry>
                <mesh filename="package://arx5_description/meshes/link3.STL" />
            </geometry>
        </collision>
    </link>
    <joint name="fr_joint3" type="revolute">
        <origin xyz="-0.264 0 0" rpy="-3.1416 0 0" />
        <parent link="fr_link2" />
        <child link="fr_link3" />
        <axis xyz="0 1 0" />
        <limit lower="-10" upper="10" effort="100" velocity="1000" />
    </joint>
    <link name="fr_link4">
        <inertial>
            <origin xyz="0.0388884702662706 0.00295168681334743 -0.0353282735009622" rpy="0 0 0" />
            <mass value="0.0809712553169999" />
            <inertia ixx="0.00013" ixy="-0.00001" ixz="-0.00006" iyy="0.00016" iyz="0.00001" izz="0.00010" />
        </inertial>
        <visual>
            <origin xyz="0 0 0" rpy="0 0 0" />
            <geometry>
                <mesh filename="package://arx5_description/meshes/link4.STL" />
            </geometry>
            <material name="">
                <color rgba="0.898039215686275 0.917647058823529 0.929411764705882 1" />
            </material>
        </visual>
        <collision>
            <origin xyz="0 0 0" rpy="0 0 0" />
            <geometry>
                <mesh filename="package://arx5_description/meshes/link4.STL" />
            </geometry>
        </collision>
    </link>
    <joint name="fr_joint4" type="revolute">
        <origin xyz="0.245 0 -0.056" rpy="0 0 0" />
        <parent link="fr_link3" />
        <child link="fr_link4" />
        <axis xyz="0 1 0" />
        <limit lower="-10" upper="10" effort="100" velocity="1000" />
    </joint>
    <link name="fr_link5">
        <inertial>
            <origin xyz="0.00289956909960302 3.15826689885766E-05 0.0526188859211408" rpy="0 0 0" />
            <mass value="0.602357399313257" />
            <inertia ixx="0.00072" ixy="0.00000" ixz="0.00005" iyy="0.00069" iyz="0.00000" izz="0.00021" />
        </inertial>
        <visual>
            <origin xyz="0 0 0" rpy="0 0 0" />
            <geometry>
                <mesh filename="package://arx5_description/meshes/link5.STL" />
            </geometry>
            <material name="">
                <color rgba="0.752941176470588 0.752941176470588 0.752941176470588 1" />
            </material>
        </visual>
        <collision>
            <origin xyz="0 0 0" rpy="0 0 0" />
            <geometry>
                <mesh filename="package://arx5_description/meshes/link5.STL" />
            </geometry>
        </collision>
    </link>
    <joint name="fr_joint5" type="revolute">
        <origin xyz="0.06575 -0.001 -0.0825" rpy="0 0 0" />
        <parent link="fr_link4" />
        <child link="fr_link5" />
        <axis xyz="0 0 1" />
        <limit lower="-10" upper="10" effort="100" velocity="1000" />
    </joint>
    <link name="fr_link6">
        <inertial>
            <origin xyz="0.0471798400661976 0.000102970421835668 -0.000138510949393961" rpy="0 0 0" />
            <mass value="0.462244960775882" />
            <inertia ixx="0.00068" ixy="0.00000" ixz="0.00000" iyy="0.00036" iyz="-0.00001" izz="0.00091" />
        </inertial>
        <visual>
            <origin xyz="0 0 0" rpy="0 0 0" />
            <geometry>
                <mesh filename="package://arx5p2/meshes/link6.STL" />
            </geometry>
            <material name="">
                <color rgba="0.898039215686275 0.917647058823529 0.929411764705882 1" />
            </material>
        </visual>
        <collision>
            <origin xyz="0 0 0" rpy="0 0 0" />
            <geometry>
                <mesh filename="package://arx5p2/meshes/link6.STL" />
            </geometry>
        </collision>
    </link>
    <joint name="fr_joint6" type="revolute">
        <origin xyz="0.02845 0 0.0825" rpy="-3.1416 0 0" />
        <parent link="fr_link5" />
        <child link="fr_link6" />
        <axis xyz="1 0 0" />
        <limit lower="-10" upper="10" effort="100" velocity="1000" />
    </joint>
    <link name="fr_link7">
        <inertial>
            <origin xyz="-0.000327642774520215 -0.00482005374028087 -0.00167540868720402" rpy="0 0 0" />
            <mass value="0.0484016660227936" />
            <inertia ixx="0.00001" ixy="0.00000" ixz="0.00000" iyy="0.00002" iyz="0.00000" izz="0.00002" />
        </inertial>
        <visual>
            <origin xyz="0 0 0" rpy="0 0 0" />
            <geometry>
                <mesh filename="package://arx5p2/meshes/link7.STL" />
            </geometry>
            <material name="">
                <color rgba="0.898039215686275 0.917647058823529 0.929411764705882 1" />
            </material>
        </visual>
        <collision>
            <origin xyz="0 0 0" rpy="0 0 0" />
            <geometry>
                <mesh filename="package://arx5p2/meshes/link7.STL" />
            </geometry>
        </collision>
    </link>
    <joint name="fr_joint7" type="prismatic">
        <origin xyz="0.073574 0.024629 0" rpy="0 0 0" />
        <parent link="fr_link6" />
        <child link="fr_link7" />
        <axis xyz="0 1 0" />
        <limit lower="0" upper="0.04765" effort="100" velocity="100" />
    </joint>
    <link name="fr_link8">
        <inertial>
            <origin xyz="-0.000327643744208572 0.00482005363510456 0.000752972893839382" rpy="0 0 0" />
            <mass value="0.0484016646136083" />
            <inertia ixx="0.00001" ixy="0.00000" ixz="0.00000" iyy="0.00002" iyz="0.00000" izz="0.00002" />
        </inertial>
        <visual>
            <origin xyz="0 0 0" rpy="0 0 0" />
            <geometry>
                <mesh filename="package://arx5p2/meshes/link8.STL" />
            </geometry>
            <material name="">
                <color rgba="0.898039215686275 0.917647058823529 0.929411764705882 1" />
            </material>
        </visual>
        <collision>
            <origin xyz="0 0 0" rpy="0 0 0" />
            <geometry>
                <mesh filename="package://arx5p2/meshes/link8.STL" />
            </geometry>
        </collision>
    </link>
    <joint name="fr_joint8" type="prismatic">
        <origin xyz="0.073574 -0.024629 0" rpy="0 0 0" />
        <parent link="fr_link6" />
        <child link="fr_link8" />
        <axis xyz="0 -1 0" />
        <limit lower="0" upper="0.04765" effort="100" velocity="100" />
    </joint>

    <!--***************************** left-rear ****************************** -->
    <link name="lr_base_link">
        <inertial>
            <origin xyz="-2.9972E-05 3.056E-05 0.027301" rpy="0 0 0" />
            <mass value="0.44038" />
            <inertia ixx="0.00017" ixy="0.00000" ixz="0.00000" iyy="0.00018" iyz="0.00000" izz="0.00016" />
        </inertial>
        <visual>
            <origin xyz="0 0 0" rpy="0 0 0" />
            <geometry>
                <mesh filename="package://arx5_description/meshes/base_link.STL" />
            </geometry>
            <material name="">
                <color rgba="0.75294 0.75294 0.75294 1" />
            </material>
        </visual>
        <collision>
            <origin xyz="0 0 0" rpy="0 0 0" />
            <geometry>
                <mesh filename="package://arx5_description/meshes/base_link.STL" />
            </geometry>
        </collision>
    </link>
    <joint name="lr_base_joint" type="fixed">
        <origin xyz="-0.309 0.307 0.903" rpy="0.0 0.0 0.0" />
        <parent link="footprint" />
        <child link="lr_base_link" />
        <axis xyz="0.0 0.0 1.0" />
    </joint>
    <link name="lr_link1">
        <inertial>
            <origin xyz="0.00609525411893452 -0.00429681977500749 0.0179590247477389" rpy="0 0 0" />
            <mass value="0.0608351104988555" />
            <inertia ixx="0.00008" ixy="0.00000" ixz="0.00001" iyy="0.00003" iyz="0.00000" izz="0.00007" />
        </inertial>
        <visual>
            <origin xyz="0 0 0" rpy="0 0 0" />
            <geometry>
                <mesh filename="package://arx5_description/meshes/link1.STL" />
            </geometry>
            <material name="">
                <color rgba="0.752941176470588 0.752941176470588 0.752941176470588 1" />
            </material>
        </visual>
        <collision>
            <origin xyz="0 0 0" rpy="0 0 0" />
            <geometry>
                <mesh filename="package://arx5_description/meshes/link1.STL" />
            </geometry>
        </collision>
    </link>
    <joint name="lr_joint1" type="revolute">
        <origin xyz="0 0 0.0603" rpy="0 0 0" />
        <parent link="lr_base_link" />
        <child link="lr_link1" />
        <axis xyz="0 0 1" />
        <limit lower="-10" upper="10" effort="100" velocity="1000" />
    </joint>
    <link name="lr_link2">
        <inertial>
            <origin xyz="-0.132382037190567 0.00220380675553821 0.000111790164679923" rpy="0 0 0" />
            <mass value="1.0733279014126" />
            <inertia ixx="0.00050" ixy="0.00000" ixz="-0.00004" iyy="0.01596" iyz="0.00000" izz="0.01602" />
        </inertial>
        <visual>
            <origin xyz="0 0 0" rpy="0 0 0" />
            <geometry>
                <mesh filename="package://arx5_description/meshes/link2.STL" />
            </geometry>
            <material name="">
                <color rgba="0.752941176470588 0.752941176470588 0.752941176470588 1" />
            </material>
        </visual>
        <collision>
            <origin xyz="0 0 0" rpy="0 0 0" />
            <geometry>
                <mesh filename="package://arx5_description/meshes/link2.STL" />
            </geometry>
        </collision>
    </link>
    <joint name="lr_joint2" type="revolute">
        <origin xyz="0.02 0 0.0402" rpy="0 0 0" />
        <parent link="lr_link1" />
        <child link="lr_link2" />
        <axis xyz="0 1 0" />
        <dynamics damping="0.0" friction="100.0"/>
        <limit lower="-10" upper="10" effort="100" velocity="1000" />
    </joint>
    <link name="lr_link3">
        <inertial>
            <origin xyz="0.187203287369961 -0.000305676361444925 -0.0514832866415513" rpy="0 0 0" />
            <mass value="0.499404738025019" />
            <inertia ixx="0.00033" ixy="-0.00006" ixz="-0.00039" iyy="0.00387" iyz="0.00001" izz="0.00383" />
        </inertial>
        <visual>
            <origin xyz="0 0 0" rpy="0 0 0" />
            <geometry>
                <mesh filename="package://arx5_description/meshes/link3.STL" />
            </geometry>
            <material name="">
                <color rgba="0.752941176470588 0.752941176470588 0.752941176470588 1" />
            </material>
        </visual>
        <collision>
            <origin xyz="0 0 0" rpy="0 0 0" />
            <geometry>
                <mesh filename="package://arx5_description/meshes/link3.STL" />
            </geometry>
        </collision>
    </link>
    <joint name="lr_joint3" type="revolute">
        <origin xyz="-0.264 0 0" rpy="-3.1416 0 0" />
        <parent link="lr_link2" />
        <child link="lr_link3" />
        <axis xyz="0 1 0" />
        <dynamics damping="0.0" friction="100.0"/>
        <limit lower="-10" upper="10" effort="100" velocity="1000" />
    </joint>
    <link name="lr_link4">
        <inertial>
            <origin xyz="0.0388884702662706 0.00295168681334743 -0.0353282735009622" rpy="0 0 0" />
            <mass value="0.0809712553169999" />
            <inertia ixx="0.00013" ixy="-0.00001" ixz="-0.00006" iyy="0.00016" iyz="0.00001" izz="0.00010" />
        </inertial>
        <visual>
            <origin xyz="0 0 0" rpy="0 0 0" />
            <geometry>
                <mesh filename="package://arx5_description/meshes/link4.STL" />
            </geometry>
            <material name="">
                <color rgba="0.898039215686275 0.917647058823529 0.929411764705882 1" />
            </material>
        </visual>
        <collision>
            <origin xyz="0 0 0" rpy="0 0 0" />
            <geometry>
                <mesh filename="package://arx5_description/meshes/link4.STL" />
            </geometry>
        </collision>
    </link>
    <joint name="lr_joint4" type="revolute">
        <origin xyz="0.245 0 -0.056" rpy="0 0 0" />
        <parent link="lr_link3" />
        <child link="lr_link4" />
        <axis xyz="0 1 0" />
        <limit lower="-10" upper="10" effort="100" velocity="1000" />
    </joint>
    <link name="lr_link5">
        <inertial>
            <origin xyz="0.00289956909960302 3.15826689885766E-05 0.0526188859211408" rpy="0 0 0" />
            <mass value="0.602357399313257" />
            <inertia ixx="0.00072" ixy="0.00000" ixz="0.00005" iyy="0.00069" iyz="0.00000" izz="0.00021" />
        </inertial>
        <visual>
            <origin xyz="0 0 0" rpy="0 0 0" />
            <geometry>
                <mesh filename="package://arx5_description/meshes/link5.STL" />
            </geometry>
            <material name="">
                <color rgba="0.752941176470588 0.752941176470588 0.752941176470588 1" />
            </material>
        </visual>
        <collision>
            <origin xyz="0 0 0" rpy="0 0 0" />
            <geometry>
                <mesh filename="package://arx5_description/meshes/link5.STL" />
            </geometry>
        </collision>
    </link>
    <joint name="lr_joint5" type="revolute">
        <origin xyz="0.06575 -0.001 -0.0825" rpy="0 0 0" />
        <parent link="lr_link4" />
        <child link="lr_link5" />
        <axis xyz="0 0 1" />
        <limit lower="-10" upper="10" effort="100" velocity="1000" />
    </joint>
    <link name="lr_link6">
        <inertial>
            <origin xyz="0.0471798400661976 0.000102970421835668 -0.000138510949393961" rpy="0 0 0" />
            <mass value="0.462244960775882" />
            <inertia ixx="0.00068" ixy="0.00000" ixz="0.00000" iyy="0.00036" iyz="-0.00001" izz="0.00091" />
        </inertial>
        <visual>
            <origin xyz="0 0 0" rpy="0 0 0" />
            <geometry>
                <mesh filename="package://arx5p2/meshes/link6.STL" />
            </geometry>
            <material name="">
                <color rgba="0.898039215686275 0.917647058823529 0.929411764705882 1" />
            </material>
        </visual>
        <collision>
            <origin xyz="0 0 0" rpy="0 0 0" />
            <geometry>
                <mesh filename="package://arx5p2/meshes/link6.STL" />
            </geometry>
        </collision>
    </link>
    <joint name="lr_joint6" type="revolute">
        <origin xyz="0.02845 0 0.0825" rpy="-3.1416 0 0" />
        <parent link="lr_link5" />
        <child link="lr_link6" />
        <axis xyz="1 0 0" />
        <limit lower="-10" upper="10" effort="100" velocity="1000" />
    </joint>
    <link name="lr_link7">
        <inertial>
            <origin xyz="-0.000327642774520215 -0.00482005374028087 -0.00167540868720402" rpy="0 0 0" />
            <mass value="0.0484016660227936" />
            <inertia ixx="0.00001" ixy="0.00000" ixz="0.00000" iyy="0.00002" iyz="0.00000" izz="0.00002" />
        </inertial>
        <visual>
            <origin xyz="0 0 0" rpy="0 0 0" />
            <geometry>
                <mesh filename="package://arx5p2/meshes/link7.STL" />
            </geometry>
            <material name="">
                <color rgba="0.898039215686275 0.917647058823529 0.929411764705882 1" />
            </material>
        </visual>
        <collision>
            <origin xyz="0 0 0" rpy="0 0 0" />
            <geometry>
                <mesh filename="package://arx5p2/meshes/link7.STL" />
            </geometry>
        </collision>
    </link>
    <joint name="lr_joint7" type="prismatic">
        <origin xyz="0.073574 0.024629 0" rpy="0 0 0" />
        <parent link="lr_link6" />
        <child link="lr_link7" />
        <axis xyz="0 1 0" />
        <limit lower="0" upper="0.04765" effort="100" velocity="100" />
    </joint>
    <link name="lr_link8">
        <inertial>
            <origin xyz="-0.000327643744208572 0.00482005363510456 0.000752972893839382" rpy="0 0 0" />
            <mass value="0.0484016646136083" />
            <inertia ixx="0.00001" ixy="0.00000" ixz="0.00000" iyy="0.00002" iyz="0.00000" izz="0.00002" />
        </inertial>
        <visual>
            <origin xyz="0 0 0" rpy="0 0 0" />
            <geometry>
                <mesh filename="package://arx5p2/meshes/link8.STL" />
            </geometry>
            <material name="">
                <color rgba="0.898039215686275 0.917647058823529 0.929411764705882 1" />
            </material>
        </visual>
        <collision>
            <origin xyz="0 0 0" rpy="0 0 0" />
            <geometry>
                <mesh filename="package://arx5p2/meshes/link8.STL" />
            </geometry>
        </collision>
    </link>
    <joint name="lr_joint8" type="prismatic">
        <origin xyz="0.073574 -0.024629 0" rpy="0 0 0" />
        <parent link="lr_link6" />
        <child link="lr_link8" />
        <axis xyz="0 -1 0" />
        <limit lower="0" upper="0.04765" effort="100" velocity="100" />
    </joint>

    <!--***************************** right-rear ****************************** -->
    <link name="rr_base_link">
        <inertial>
            <origin xyz="-2.9972E-05 3.056E-05 0.027301" rpy="0 0 0" />
            <mass value="0.44038" />
            <inertia ixx="0.00017" ixy="0.00000" ixz="0.00000" iyy="0.00018" iyz="0.00000" izz="0.00016" />
        </inertial>
        <visual>
            <origin xyz="0 0 0" rpy="0 0 0" />
            <geometry>
                <mesh filename="package://arx5_description/meshes/base_link.STL" />
            </geometry>
            <material name="">
                <color rgba="0.75294 0.75294 0.75294 1" />
            </material>
        </visual>
        <collision>
            <origin xyz="0 0 0" rpy="0 0 0" />
            <geometry>
                <mesh filename="package://arx5_description/meshes/base_link.STL" />
            </geometry>
        </collision>
    </link>
    <joint name="rr_base_joint" type="fixed">
        <origin xyz="-0.309 -0.307 0.903" rpy="0.0 0.0 0.0" />
        <parent link="footprint" />
        <child link="rr_base_link" />
        <axis xyz="0.0 0.0 1.0" />
    </joint>
    <link name="rr_link1">
        <inertial>
            <origin xyz="0.00609525411893452 -0.00429681977500749 0.0179590247477389" rpy="0 0 0" />
            <mass value="0.0608351104988555" />
            <inertia ixx="0.00008" ixy="0.00000" ixz="0.00001" iyy="0.00003" iyz="0.00000" izz="0.00007" />
        </inertial>
        <visual>
            <origin xyz="0 0 0" rpy="0 0 0" />
            <geometry>
                <mesh filename="package://arx5_description/meshes/link1.STL" />
            </geometry>
            <material name="">
                <color rgba="0.752941176470588 0.752941176470588 0.752941176470588 1" />
            </material>
        </visual>
        <collision>
            <origin xyz="0 0 0" rpy="0 0 0" />
            <geometry>
                <mesh filename="package://arx5_description/meshes/link1.STL" />
            </geometry>
        </collision>
    </link>
    <joint name="rr_joint1" type="revolute">
        <origin xyz="0 0 0.0603" rpy="0 0 0" />
        <parent link="rr_base_link" />
        <child link="rr_link1" />
        <axis xyz="0 0 1" />
        <limit lower="-10" upper="10" effort="100" velocity="1000" />
    </joint>
    <link name="rr_link2">
        <inertial>
            <origin xyz="-0.132382037190567 0.00220380675553821 0.000111790164679923" rpy="0 0 0" />
            <mass value="1.0733279014126" />
            <inertia ixx="0.00050" ixy="0.00000" ixz="-0.00004" iyy="0.01596" iyz="0.00000" izz="0.01602" />
        </inertial>
        <visual>
            <origin xyz="0 0 0" rpy="0 0 0" />
            <geometry>
                <mesh filename="package://arx5_description/meshes/link2.STL" />
            </geometry>
            <material name="">
                <color rgba="0.752941176470588 0.752941176470588 0.752941176470588 1" />
            </material>
        </visual>
        <collision>
            <origin xyz="0 0 0" rpy="0 0 0" />
            <geometry>
                <mesh filename="package://arx5_description/meshes/link2.STL" />
            </geometry>
        </collision>
    </link>
    <joint name="rr_joint2" type="revolute">
        <origin xyz="0.02 0 0.0402" rpy="0 0 0" />
        <parent link="rr_link1" />
        <child link="rr_link2" />
        <axis xyz="0 1 0" />
        <limit lower="-10" upper="10" effort="100" velocity="1000" />
    </joint>
    <link name="rr_link3">
        <inertial>
            <origin xyz="0.187203287369961 -0.000305676361444925 -0.0514832866415513" rpy="0 0 0" />
            <mass value="0.499404738025019" />
            <inertia ixx="0.00033" ixy="-0.00006" ixz="-0.00039" iyy="0.00387" iyz="0.00001" izz="0.00383" />
        </inertial>
        <visual>
            <origin xyz="0 0 0" rpy="0 0 0" />
            <geometry>
                <mesh filename="package://arx5_description/meshes/link3.STL" />
            </geometry>
            <material name="">
                <color rgba="0.752941176470588 0.752941176470588 0.752941176470588 1" />
            </material>
        </visual>
        <collision>
            <origin xyz="0 0 0" rpy="0 0 0" />
            <geometry>
                <mesh filename="package://arx5_description/meshes/link3.STL" />
            </geometry>
        </collision>
    </link>
    <joint name="rr_joint3" type="revolute">
        <origin xyz="-0.264 0 0" rpy="-3.1416 0 0" />
        <parent link="rr_link2" />
        <child link="rr_link3" />
        <axis xyz="0 1 0" />
        <limit lower="-10" upper="10" effort="100" velocity="1000" />
    </joint>
    <link name="rr_link4">
        <inertial>
            <origin xyz="0.0388884702662706 0.00295168681334743 -0.0353282735009622" rpy="0 0 0" />
            <mass value="0.0809712553169999" />
            <inertia ixx="0.00013" ixy="-0.00001" ixz="-0.00006" iyy="0.00016" iyz="0.00001" izz="0.00010" />
        </inertial>
        <visual>
            <origin xyz="0 0 0" rpy="0 0 0" />
            <geometry>
                <mesh filename="package://arx5_description/meshes/link4.STL" />
            </geometry>
            <material name="">
                <color rgba="0.898039215686275 0.917647058823529 0.929411764705882 1" />
            </material>
        </visual>
        <collision>
            <origin xyz="0 0 0" rpy="0 0 0" />
            <geometry>
                <mesh filename="package://arx5_description/meshes/link4.STL" />
            </geometry>
        </collision>
    </link>
    <joint name="rr_joint4" type="revolute">
        <origin xyz="0.245 0 -0.056" rpy="0 0 0" />
        <parent link="rr_link3" />
        <child link="rr_link4" />
        <axis xyz="0 1 0" />
        <limit lower="-10" upper="10" effort="100" velocity="1000" />
    </joint>
    <link name="rr_link5">
        <inertial>
            <origin xyz="0.00289956909960302 3.15826689885766E-05 0.0526188859211408" rpy="0 0 0" />
            <mass value="0.602357399313257" />
            <inertia ixx="0.00072" ixy="0.00000" ixz="0.00005" iyy="0.00069" iyz="0.00000" izz="0.00021" />
        </inertial>
        <visual>
            <origin xyz="0 0 0" rpy="0 0 0" />
            <geometry>
                <mesh filename="package://arx5_description/meshes/link5.STL" />
            </geometry>
            <material name="">
                <color rgba="0.752941176470588 0.752941176470588 0.752941176470588 1" />
            </material>
        </visual>
        <collision>
            <origin xyz="0 0 0" rpy="0 0 0" />
            <geometry>
                <mesh filename="package://arx5_description/meshes/link5.STL" />
            </geometry>
        </collision>
    </link>
    <joint name="rr_joint5" type="revolute">
        <origin xyz="0.06575 -0.001 -0.0825" rpy="0 0 0" />
        <parent link="rr_link4" />
        <child link="rr_link5" />
        <axis xyz="0 0 1" />
        <limit lower="-10" upper="10" effort="100" velocity="1000" />
    </joint>
    <link name="rr_link6">
        <inertial>
            <origin xyz="0.0471798400661976 0.000102970421835668 -0.000138510949393961" rpy="0 0 0" />
            <mass value="0.462244960775882" />
            <inertia ixx="0.00068" ixy="0.00000" ixz="0.00000" iyy="0.00036" iyz="-0.00001" izz="0.00091" />
        </inertial>
        <visual>
            <origin xyz="0 0 0" rpy="0 0 0" />
            <geometry>
                <mesh filename="package://arx5p2/meshes/link6.STL" />
            </geometry>
            <material name="">
                <color rgba="0.898039215686275 0.917647058823529 0.929411764705882 1" />
            </material>
        </visual>
        <collision>
            <origin xyz="0 0 0" rpy="0 0 0" />
            <geometry>
                <mesh filename="package://arx5p2/meshes/link6.STL" />
            </geometry>
        </collision>
    </link>
    <joint name="rr_joint6" type="revolute">
        <origin xyz="0.02845 0 0.0825" rpy="-3.1416 0 0" />
        <parent link="rr_link5" />
        <child link="rr_link6" />
        <axis xyz="1 0 0" />
        <limit lower="-10" upper="10" effort="100" velocity="1000" />
    </joint>
    <link name="rr_link7">
        <inertial>
            <origin xyz="-0.000327642774520215 -0.00482005374028087 -0.00167540868720402" rpy="0 0 0" />
            <mass value="0.0484016660227936" />
            <inertia ixx="0.00001" ixy="0.00000" ixz="0.00000" iyy="0.00002" iyz="0.00000" izz="0.00002" />
        </inertial>
        <visual>
            <origin xyz="0 0 0" rpy="0 0 0" />
            <geometry>
                <mesh filename="package://arx5p2/meshes/link7.STL" />
            </geometry>
            <material name="">
                <color rgba="0.898039215686275 0.917647058823529 0.929411764705882 1" />
            </material>
        </visual>
        <collision>
            <origin xyz="0 0 0" rpy="0 0 0" />
            <geometry>
                <mesh filename="package://arx5p2/meshes/link7.STL" />
            </geometry>
        </collision>
    </link>
    <joint name="rr_joint7" type="prismatic">
        <origin xyz="0.073574 0.024629 0" rpy="0 0 0" />
        <parent link="rr_link6" />
        <child link="rr_link7" />
        <axis xyz="0 1 0" />
        <limit lower="0" upper="0.04765" effort="100" velocity="100" />
    </joint>
    <link name="rr_link8">
        <inertial>
            <origin xyz="-0.000327643744208572 0.00482005363510456 0.000752972893839382" rpy="0 0 0" />
            <mass value="0.0484016646136083" />
            <inertia ixx="0.00001" ixy="0.00000" ixz="0.00000" iyy="0.00002" iyz="0.00000" izz="0.00002" />
        </inertial>
        <visual>
            <origin xyz="0 0 0" rpy="0 0 0" />
            <geometry>
                <mesh filename="package://arx5p2/meshes/link8.STL" />
            </geometry>
            <material name="">
                <color rgba="0.898039215686275 0.917647058823529 0.929411764705882 1" />
            </material>
        </visual>
        <collision>
            <origin xyz="0 0 0" rpy="0 0 0" />
            <geometry>
                <mesh filename="package://arx5p2/meshes/link8.STL" />
            </geometry>
        </collision>
    </link>
    <joint name="rr_joint8" type="prismatic">
        <origin xyz="0.073574 -0.024629 0" rpy="0 0 0" />
        <parent link="rr_link6" />
        <child link="rr_link8" />
        <axis xyz="0 -1 0" />
        <limit lower="0" upper="0.04765" effort="100" velocity="100" />
    </joint>

    <transmission name="trans_fl_joint1">
        <type>transmission_interface/SimpleTransmission</type>
        <joint name="fl_joint1">
            <hardwareInterface>hardware_interface/PositionJointInterface</hardwareInterface>
        </joint>
        <actuator name="fl_joint1_motor">
            <hardwareInterface>hardware_interface/PositionJointInterface</hardwareInterface>
            <mechanicalReduction>1</mechanicalReduction>
        </actuator>
    </transmission>
    <transmission name="trans_fl_joint2">
        <type>transmission_interface/SimpleTransmission</type>
        <joint name="fl_joint2">
            <hardwareInterface>hardware_interface/PositionJointInterface</hardwareInterface>
        </joint>
        <actuator name="fl_joint2_motor">
            <hardwareInterface>hardware_interface/PositionJointInterface</hardwareInterface>
            <mechanicalReduction>1</mechanicalReduction>
        </actuator>
    </transmission>
    <transmission name="trans_fl_joint3">
        <type>transmission_interface/SimpleTransmission</type>
        <joint name="fl_joint3">
            <hardwareInterface>hardware_interface/PositionJointInterface</hardwareInterface>
        </joint>
        <actuator name="fl_joint3_motor">
            <hardwareInterface>hardware_interface/PositionJointInterface</hardwareInterface>
            <mechanicalReduction>1</mechanicalReduction>
        </actuator>
    </transmission>
    <transmission name="trans_fl_joint4">
        <type>transmission_interface/SimpleTransmission</type>
        <joint name="fl_joint4">
            <hardwareInterface>hardware_interface/PositionJointInterface</hardwareInterface>
        </joint>
        <actuator name="fl_joint4_motor">
            <hardwareInterface>hardware_interface/PositionJointInterface</hardwareInterface>
            <mechanicalReduction>1</mechanicalReduction>
        </actuator>
    </transmission>
    <transmission name="trans_fl_joint5">
        <type>transmission_interface/SimpleTransmission</type>
        <joint name="fl_joint5">
            <hardwareInterface>hardware_interface/PositionJointInterface</hardwareInterface>
        </joint>
        <actuator name="fl_joint5_motor">
            <hardwareInterface>hardware_interface/PositionJointInterface</hardwareInterface>
            <mechanicalReduction>1</mechanicalReduction>
        </actuator>
    </transmission>
    <transmission name="trans_fl_joint6">
        <type>transmission_interface/SimpleTransmission</type>
        <joint name="fl_joint6">
            <hardwareInterface>hardware_interface/PositionJointInterface</hardwareInterface>
        </joint>
        <actuator name="fl_joint6_motor">
            <hardwareInterface>hardware_interface/PositionJointInterface</hardwareInterface>
            <mechanicalReduction>1</mechanicalReduction>
        </actuator>
    </transmission>
    <transmission name="trans_fl_joint7">
        <type>transmission_interface/SimpleTransmission</type>
        <joint name="fl_joint7">
            <hardwareInterface>hardware_interface/PositionJointInterface</hardwareInterface>
        </joint>
        <actuator name="fl_joint7_motor">
            <hardwareInterface>hardware_interface/PositionJointInterface</hardwareInterface>
            <mechanicalReduction>1</mechanicalReduction>
        </actuator>
    </transmission>
    <transmission name="trans_fl_joint8">
        <type>transmission_interface/SimpleTransmission</type>
        <joint name="fl_joint8">
            <hardwareInterface>hardware_interface/PositionJointInterface</hardwareInterface>
        </joint>
        <actuator name="fl_joint8_motor">
            <hardwareInterface>hardware_interface/PositionJointInterface</hardwareInterface>
            <mechanicalReduction>1</mechanicalReduction>
        </actuator>
    </transmission>

    <transmission name="trans_fr_joint1">
        <type>transmission_interface/SimpleTransmission</type>
        <joint name="fr_joint1">
            <hardwareInterface>hardware_interface/PositionJointInterface</hardwareInterface>
        </joint>
        <actuator name="fr_joint1_motor">
            <hardwareInterface>hardware_interface/PositionJointInterface</hardwareInterface>
            <mechanicalReduction>1</mechanicalReduction>
        </actuator>
    </transmission>
    <transmission name="trans_fr_joint2">
        <type>transmission_interface/SimpleTransmission</type>
        <joint name="fr_joint2">
            <hardwareInterface>hardware_interface/PositionJointInterface</hardwareInterface>
        </joint>
        <actuator name="fr_joint2_motor">
            <hardwareInterface>hardware_interface/PositionJointInterface</hardwareInterface>
            <mechanicalReduction>1</mechanicalReduction>
        </actuator>
    </transmission>
    <transmission name="trans_fr_joint3">
        <type>transmission_interface/SimpleTransmission</type>
        <joint name="fr_joint3">
            <hardwareInterface>hardware_interface/PositionJointInterface</hardwareInterface>
        </joint>
        <actuator name="fr_joint3_motor">
            <hardwareInterface>hardware_interface/PositionJointInterface</hardwareInterface>
            <mechanicalReduction>1</mechanicalReduction>
        </actuator>
    </transmission>
    <transmission name="trans_fr_joint4">
        <type>transmission_interface/SimpleTransmission</type>
        <joint name="fr_joint4">
            <hardwareInterface>hardware_interface/PositionJointInterface</hardwareInterface>
        </joint>
        <actuator name="fr_joint4_motor">
            <hardwareInterface>hardware_interface/PositionJointInterface</hardwareInterface>
            <mechanicalReduction>1</mechanicalReduction>
        </actuator>
    </transmission>
    <transmission name="trans_fr_joint5">
        <type>transmission_interface/SimpleTransmission</type>
        <joint name="fr_joint5">
            <hardwareInterface>hardware_interface/PositionJointInterface</hardwareInterface>
        </joint>
        <actuator name="fr_joint5_motor">
            <hardwareInterface>hardware_interface/PositionJointInterface</hardwareInterface>
            <mechanicalReduction>1</mechanicalReduction>
        </actuator>
    </transmission>
    <transmission name="trans_fr_joint6">
        <type>transmission_interface/SimpleTransmission</type>
        <joint name="fr_joint6">
            <hardwareInterface>hardware_interface/PositionJointInterface</hardwareInterface>
        </joint>
        <actuator name="fr_joint6_motor">
            <hardwareInterface>hardware_interface/PositionJointInterface</hardwareInterface>
            <mechanicalReduction>1</mechanicalReduction>
        </actuator>
    </transmission>
    <transmission name="trans_fr_joint7">
        <type>transmission_interface/SimpleTransmission</type>
        <joint name="fr_joint7">
            <hardwareInterface>hardware_interface/PositionJointInterface</hardwareInterface>
        </joint>
        <actuator name="fr_joint7_motor">
            <hardwareInterface>hardware_interface/PositionJointInterface</hardwareInterface>
            <mechanicalReduction>1</mechanicalReduction>
        </actuator>
    </transmission>
    <transmission name="trans_fr_joint8">
        <type>transmission_interface/SimpleTransmission</type>
        <joint name="fr_joint8">
            <hardwareInterface>hardware_interface/PositionJointInterface</hardwareInterface>
        </joint>
        <actuator name="fr_joint8_motor">
            <hardwareInterface>hardware_interface/PositionJointInterface</hardwareInterface>
            <mechanicalReduction>1</mechanicalReduction>
        </actuator>
    </transmission>

    <transmission name="trans_lr_joint1">
        <type>transmission_interface/SimpleTransmission</type>
        <joint name="lr_joint1">
            <hardwareInterface>hardware_interface/PositionJointInterface</hardwareInterface>
        </joint>
        <actuator name="lr_joint1_motor">
            <hardwareInterface>hardware_interface/PositionJointInterface</hardwareInterface>
            <mechanicalReduction>1</mechanicalReduction>
        </actuator>
    </transmission>
    <transmission name="trans_lr_joint2">
        <type>transmission_interface/SimpleTransmission</type>
        <joint name="lr_joint2">
            <hardwareInterface>hardware_interface/PositionJointInterface</hardwareInterface>
        </joint>
        <actuator name="lr_joint2_motor">
            <hardwareInterface>hardware_interface/PositionJointInterface</hardwareInterface>
            <mechanicalReduction>1</mechanicalReduction>
        </actuator>
    </transmission>
    <transmission name="trans_lr_joint3">
        <type>transmission_interface/SimpleTransmission</type>
        <joint name="lr_joint3">
            <hardwareInterface>hardware_interface/PositionJointInterface</hardwareInterface>
        </joint>
        <actuator name="lr_joint3_motor">
            <hardwareInterface>hardware_interface/PositionJointInterface</hardwareInterface>
            <mechanicalReduction>1</mechanicalReduction>
        </actuator>
    </transmission>
    <transmission name="trans_lr_joint4">
        <type>transmission_interface/SimpleTransmission</type>
        <joint name="lr_joint4">
            <hardwareInterface>hardware_interface/PositionJointInterface</hardwareInterface>
        </joint>
        <actuator name="lr_joint4_motor">
            <hardwareInterface>hardware_interface/PositionJointInterface</hardwareInterface>
            <mechanicalReduction>1</mechanicalReduction>
        </actuator>
    </transmission>
    <transmission name="trans_lr_joint5">
        <type>transmission_interface/SimpleTransmission</type>
        <joint name="lr_joint5">
            <hardwareInterface>hardware_interface/PositionJointInterface</hardwareInterface>
        </joint>
        <actuator name="lr_joint5_motor">
            <hardwareInterface>hardware_interface/PositionJointInterface</hardwareInterface>
            <mechanicalReduction>1</mechanicalReduction>
        </actuator>
    </transmission>
    <transmission name="trans_lr_joint6">
        <type>transmission_interface/SimpleTransmission</type>
        <joint name="lr_joint6">
            <hardwareInterface>hardware_interface/PositionJointInterface</hardwareInterface>
        </joint>
        <actuator name="lr_joint6_motor">
            <hardwareInterface>hardware_interface/PositionJointInterface</hardwareInterface>
            <mechanicalReduction>1</mechanicalReduction>
        </actuator>
    </transmission>
        <transmission name="trans_lr_joint7">
        <type>transmission_interface/SimpleTransmission</type>
        <joint name="lr_joint7">
            <hardwareInterface>hardware_interface/PositionJointInterface</hardwareInterface>
        </joint>
        <actuator name="lr_joint7_motor">
            <hardwareInterface>hardware_interface/PositionJointInterface</hardwareInterface>
            <mechanicalReduction>1</mechanicalReduction>
        </actuator>
    </transmission>
    <transmission name="trans_lr_joint8">
        <type>transmission_interface/SimpleTransmission</type>
        <joint name="lr_joint8">
            <hardwareInterface>hardware_interface/PositionJointInterface</hardwareInterface>
        </joint>
        <actuator name="lr_joint8_motor">
            <hardwareInterface>hardware_interface/PositionJointInterface</hardwareInterface>
            <mechanicalReduction>1</mechanicalReduction>
        </actuator>
    </transmission>
    <transmission name="trans_rr_joint1">
        <type>transmission_interface/SimpleTransmission</type>
        <joint name="rr_joint1">
            <hardwareInterface>hardware_interface/PositionJointInterface</hardwareInterface>
        </joint>
        <actuator name="rr_joint1_motor">
            <hardwareInterface>hardware_interface/PositionJointInterface</hardwareInterface>
            <mechanicalReduction>1</mechanicalReduction>
        </actuator>
    </transmission>
    <transmission name="trans_rr_joint2">
        <type>transmission_interface/SimpleTransmission</type>
        <joint name="rr_joint2">
            <hardwareInterface>hardware_interface/PositionJointInterface</hardwareInterface>
        </joint>
        <actuator name="rr_joint2_motor">
            <hardwareInterface>hardware_interface/PositionJointInterface</hardwareInterface>
            <mechanicalReduction>1</mechanicalReduction>
        </actuator>
    </transmission>
    <transmission name="trans_rr_joint3">
        <type>transmission_interface/SimpleTransmission</type>
        <joint name="rr_joint3">
            <hardwareInterface>hardware_interface/PositionJointInterface</hardwareInterface>
        </joint>
        <actuator name="rr_joint3_motor">
            <hardwareInterface>hardware_interface/PositionJointInterface</hardwareInterface>
            <mechanicalReduction>1</mechanicalReduction>
        </actuator>
    </transmission>
    <transmission name="trans_rr_joint4">
        <type>transmission_interface/SimpleTransmission</type>
        <joint name="rr_joint4">
            <hardwareInterface>hardware_interface/PositionJointInterface</hardwareInterface>
        </joint>
        <actuator name="rr_joint4_motor">
            <hardwareInterface>hardware_interface/PositionJointInterface</hardwareInterface>
            <mechanicalReduction>1</mechanicalReduction>
        </actuator>
    </transmission>
    <transmission name="trans_rr_joint5">
        <type>transmission_interface/SimpleTransmission</type>
        <joint name="rr_joint5">
            <hardwareInterface>hardware_interface/PositionJointInterface</hardwareInterface>
        </joint>
        <actuator name="rr_joint5_motor">
            <hardwareInterface>hardware_interface/PositionJointInterface</hardwareInterface>
            <mechanicalReduction>1</mechanicalReduction>
        </actuator>
    </transmission>
    <transmission name="trans_rr_joint6">
        <type>transmission_interface/SimpleTransmission</type>
        <joint name="rr_joint6">
            <hardwareInterface>hardware_interface/PositionJointInterface</hardwareInterface>
        </joint>
        <actuator name="rr_joint6_motor">
            <hardwareInterface>hardware_interface/PositionJointInterface</hardwareInterface>
            <mechanicalReduction>1</mechanicalReduction>
        </actuator>
    </transmission>
    <transmission name="trans_rr_joint7">
        <type>transmission_interface/SimpleTransmission</type>
        <joint name="rr_joint7">
            <hardwareInterface>hardware_interface/PositionJointInterface</hardwareInterface>
        </joint>
        <actuator name="rr_joint7_motor">
            <hardwareInterface>hardware_interface/PositionJointInterface</hardwareInterface>
            <mechanicalReduction>1</mechanicalReduction>
        </actuator>
    </transmission>
    <transmission name="trans_rr_joint8">
        <type>transmission_interface/SimpleTransmission</type>
        <joint name="rr_joint8">
            <hardwareInterface>hardware_interface/PositionJointInterface</hardwareInterface>
        </joint>
        <actuator name="rr_joint8_motor">
            <hardwareInterface>hardware_interface/PositionJointInterface</hardwareInterface>
            <mechanicalReduction>1</mechanicalReduction>
        </actuator>
    </transmission>



    <!-- position controller -->
    <!-- <gazebo>
        <plugin name="base_controller" filename="libgazebo_ros_planar_move.so">
            <robotNamespace>/</robotNamespace>
            <commandTopic>cmd_vel</commandTopic>
            <odometryTopic>odom</odometryTopic>
            <odometryFrame>/odom</odometryFrame>
            <odometryRate>100.0</odometryRate>
            <robotBaseFrame>box</robotBaseFrame>
            <broadcastTF>false</broadcastTF>
        </plugin>
    </gazebo> -->

</robot>

